Traceback (most recent call last):
  File "/home/sourabh/miniconda3/envs/jbook/lib/python3.8/site-packages/jupyter_cache/executors/utils.py", line 51, in single_nb_execution
    executenb(
  File "/home/sourabh/miniconda3/envs/jbook/lib/python3.8/site-packages/nbclient/client.py", line 1112, in execute
    return NotebookClient(nb=nb, resources=resources, km=km, **kwargs).execute()
  File "/home/sourabh/miniconda3/envs/jbook/lib/python3.8/site-packages/nbclient/util.py", line 74, in wrapped
    return just_run(coro(*args, **kwargs))
  File "/home/sourabh/miniconda3/envs/jbook/lib/python3.8/site-packages/nbclient/util.py", line 53, in just_run
    return loop.run_until_complete(coro)
  File "/home/sourabh/miniconda3/envs/jbook/lib/python3.8/asyncio/base_events.py", line 616, in run_until_complete
    return future.result()
  File "/home/sourabh/miniconda3/envs/jbook/lib/python3.8/site-packages/nbclient/client.py", line 553, in async_execute
    await self.async_execute_cell(
  File "/home/sourabh/miniconda3/envs/jbook/lib/python3.8/site-packages/nbclient/client.py", line 857, in async_execute_cell
    self._check_raise_for_error(cell, exec_reply)
  File "/home/sourabh/miniconda3/envs/jbook/lib/python3.8/site-packages/nbclient/client.py", line 760, in _check_raise_for_error
    raise CellExecutionError.from_cell_and_msg(cell, exec_reply_content)
nbclient.exceptions.CellExecutionError: An error occurred while executing the following cell:
------------------
# Import matplotlib and seaborn
# Remember the line of code to set matplotlib figures to inline in Jupyter

## DO NOT DELETE THE PROVIDED LINES OF CODE
## (they are included to make sure you get decent looking plots)
plt.figure(figsize=(15,4))

#a list of regions, from the most southern to northern 
latitude_order = ['spain','maritime_alps','languedoc','various_south_east',
                  'gaillac_south_west','southern_rhone_valley','bordeaux',
                  'northern_rhone_valley','auvergne','savoie','northern_italy',
                  'beaujolais_maconnais','vendee_poitou_charente','switzerland_leman_lake',
                  'jura','high_loire_valley','low_loire_valley','burgundy','auxerre_avalon',
                  'champagne_2','southern_lorraine','alsace','northern_lorraine',
                  'germany','ile_de_france','champagne_1','luxembourg'] 
                    
# Put your code here

plt.xticks(rotation=90) #Rotates x axis labels so that they are readable

------------------

[0;31m---------------------------------------------------------------------------[0m
[0;31mNameError[0m                                 Traceback (most recent call last)
[0;32m/tmp/ipykernel_74913/3708331264.py[0m in [0;36m<module>[0;34m[0m
[1;32m      4[0m [0;31m## DO NOT DELETE THE PROVIDED LINES OF CODE[0m[0;34m[0m[0;34m[0m[0;34m[0m[0m
[1;32m      5[0m [0;31m## (they are included to make sure you get decent looking plots)[0m[0;34m[0m[0;34m[0m[0;34m[0m[0m
[0;32m----> 6[0;31m [0mplt[0m[0;34m.[0m[0mfigure[0m[0;34m([0m[0mfigsize[0m[0;34m=[0m[0;34m([0m[0;36m15[0m[0;34m,[0m[0;36m4[0m[0;34m)[0m[0;34m)[0m[0;34m[0m[0;34m[0m[0m
[0m[1;32m      7[0m [0;34m[0m[0m
[1;32m      8[0m [0;31m#a list of regions, from the most southern to northern[0m[0;34m[0m[0;34m[0m[0;34m[0m[0m

[0;31mNameError[0m: name 'plt' is not defined
NameError: name 'plt' is not defined

