Traceback (most recent call last):
  File "/home/sourabh/miniconda3/envs/jbook/lib/python3.8/site-packages/jupyter_cache/executors/utils.py", line 51, in single_nb_execution
    executenb(
  File "/home/sourabh/miniconda3/envs/jbook/lib/python3.8/site-packages/nbclient/client.py", line 1112, in execute
    return NotebookClient(nb=nb, resources=resources, km=km, **kwargs).execute()
  File "/home/sourabh/miniconda3/envs/jbook/lib/python3.8/site-packages/nbclient/util.py", line 74, in wrapped
    return just_run(coro(*args, **kwargs))
  File "/home/sourabh/miniconda3/envs/jbook/lib/python3.8/site-packages/nbclient/util.py", line 53, in just_run
    return loop.run_until_complete(coro)
  File "/home/sourabh/miniconda3/envs/jbook/lib/python3.8/asyncio/base_events.py", line 616, in run_until_complete
    return future.result()
  File "/home/sourabh/miniconda3/envs/jbook/lib/python3.8/site-packages/nbclient/client.py", line 553, in async_execute
    await self.async_execute_cell(
  File "/home/sourabh/miniconda3/envs/jbook/lib/python3.8/site-packages/nbclient/client.py", line 857, in async_execute_cell
    self._check_raise_for_error(cell, exec_reply)
  File "/home/sourabh/miniconda3/envs/jbook/lib/python3.8/site-packages/nbclient/client.py", line 760, in _check_raise_for_error
    raise CellExecutionError.from_cell_and_msg(cell, exec_reply_content)
nbclient.exceptions.CellExecutionError: An error occurred while executing the following cell:
------------------
@M02586:164:000000000-AYBV7:1:2119:13975:24958 1:N:0:1
ACGTTGTGCCAGCCGGGTGAGAAAGTAGCTGTCCGTTTCGCTGGTCTGGTCAATATGCGGGATCTTAACGCTATCAAGTTCCTGCGGGATTACTGGCAGATCTAATTTATTCCGGCTTGAAATGATTCTGACAATCGCGCCGAGCGTGTAATCATCGTAAGACTGG
+
CCCCCGGGGGGGFGGGGGGFFEGGGGGGGFCFEEGFGFFFGGGGGGGGGGGGGGFGGFG@:CFGGGGGGGGGGGGGGFFGGFFGGDGGGGGGGGFGFGGFGGGGGGGGGGD<FGGGGGGGGGGGGGGGFFFFGFF8CGGDFFEGGGGGGFGGDFGGG<DCFGGCFG
@M02586:164:000000000-AYBV7:1:2119:13272:24958 1:N:0:1
CACTCACTAGCGACCCACTTGGAGGTCGCCAAAAGCAATATTATCCATATCTCGGAGGATTTGGACCAGATCCAGGTCGTCATCGAATTGCCTGGAGAACGGCACGAACTTGGTGCTACGACGAAGTGGAAACGCACAGCAACTTCTGGAGGGAGTGTTGGATCGA
+
CCCCCGGGGGGGGGGGGGGGGGGGGGGGGGGGGGGGGGGGGGGGGGGGGGGGGGGGGGGGGGGGGGGGFGGGGGGGGGGGGGGGGGGGGGGGGGGGDFFGGGGGGGGGGGGGGGGGGGGGGGGCFGGGGGGGGGGDGGGGGGGGGGGGFFG:@GGFGGGGGGG5>,

------------------

[0;36m  File [0;32m"/tmp/ipykernel_34839/1621690197.py"[0;36m, line [0;32m1[0m
[0;31m    @M02586:164:000000000-AYBV7:1:2119:13975:24958 1:N:0:1[0m
[0m           ^[0m
[0;31mSyntaxError[0m[0;31m:[0m invalid syntax

SyntaxError: invalid syntax (1621690197.py, line 1)

